Workbook
Name NativeTimeline_Date_Registered: #N/A
Name Slicer_Age_Groups: #N/A
Name Slicer_Gender: #N/A
Name Slicer_State: #N/A

Sheet Dataset
A1: Customer_ID | B1: Age | C1: Gender | D1: State | E1: Date_Registered | F1: Verification_Status | G1: Activation_Status | H1: Days_to_Activate | I1: Account_Type | J1: Monthly_Transactions | K1: Monthly_Transaction_Value | L1: Customer_Satisfaction_Score
A2: CUST0001 | B2: 58 | C2: Male | D2: Lagos | E2: 2026-03-12 | F2: Verified | G2: Activated | H2: 1 | I2: Current | J2: 69 | K2: 201756 | L2: 5
A3: CUST0199 | B3: 20 | C3: Male | D3: Lagos | E3: 2026-06-04 | F3: Verified | G3: Not Activated | I3: Savings | J3: 5 | K3: 52005 | L3: 4
A4: CUST0194 | B4: 23 | C4: Female | D4: Ogun | E4: 2026-06-17 | F4: Verified | G4: Activated | H4: 3 | I4: Current | J4: 34 | K4: 364072 | L4: 5
A5: CUST0193 | B5: 25 | C5: Female | D5: Enugu | E5: 2026-04-12 | F5: Verified | G5: Not Activated | I5: Current | J5: 2 | K5: 4378 | L5: 3
A6: CUST0185 | B6: 20 | C6: Male | D6: Lagos | E6: 2026-03-27 | F6: Verified | G6: Activated | H6: 2 | I6: Current | J6: 65 | K6: 246350 | L6: 4
A7: CUST0184 | B7: 24 | C7: Female | D7: Lagos | E7: 2026-03-28 | F7: Verified | G7: Activated | H7: 2 | I7: Savings | J7: 65 | K7: 524940 | L7: 5
A8: CUST0007 | B8: 60 | C8: Female | D8: Rivers | E8: 2026-06-24 | F8: Verified | G8: Activated | H8: 2 | I8: Savings | J8: 31 | K8: 129487 | L8: 4
A9: CUST0178 | B9: 38 | C9: Female | D9: Kaduna | E9: 2026-02-03 | F9: Verified | G9: Activated | H9: 1 | I9: Savings | J9: 59 | K9: 206913 | L9: 4
A10: CUST0009 | B10: 38 | C10: Female | D10: Lagos | E10: 2026-02-24 | F10: Pending | G10: Not Activated | I10: Current | J10: 1 | K10: 9679 | L10: 4
A11: CUST0177 | B11: 47 | C11: Male | D11: Rivers | E11: 2026-02-10 | F11: Verified | G11: Activated | H11: 3 | I11: Savings | J11: 18 | K11: 119178 | L11: 5
A12: CUST0011 | B12: 41 | C12: Male | D12: Kaduna | E12: 2026-02-05 | F12: Verified | G12: Activated | H12: 0 | I12: Current | J12: 19 | K12: 223820 | L12: 3
A13: CUST0012 | B13: 45 | C13: Male | D13: Lagos | E13: 2026-06-02 | F13: Pending | G13: Not Activated | I13: Premium | J13: 0 | K13: 0 | L13: 3
A14: CUST0176 | B14: 19 | C14: Female | D14: Enugu | E14: 2026-05-20 | F14: Verified | G14: Not Activated | I14: Savings | J14: 5 | K14: 40765 | L14: 3
A15: CUST0014 | B15: 50 | C15: Male | D15: Enugu | E15: 2026-03-18 | F15: Verified | G15: Activated | H15: 3 | I15: Savings | J15: 20 | K15: 206740 | L15: 5
A16: CUST0015 | B16: 18 | C16: Female | D16: Abuja | E16: 2026-01-29 | F16: Pending | G16: Not Activated | I16: Current | J16: 2 | K16: 10846 | L16: 1
A17: CUST0016 | B17: 33 | C17: Male | D17: Lagos | E17: 2026-05-05 | F17: Verified | G17: Not Activated | I17: Savings | J17: 1 | K17: 3603 | L17: 4
A18: CUST0175 | B18: 19 | C18: Male | D18: Lagos | E18: 2026-06-14 | F18: Verified | G18: Activated | H18: 3 | I18: Current | J18: 53 | K18: 616231 | L18: 5
A19: CUST0018 | B19: 60 | C19: Female | D19: Abuja | E19: 2026-05-13 | F19: Verified | G19: Activated | H19: 1 | I19: Savings | J19: 75 | K19: 793125 | L19: 3
A20: CUST0019 | B20: 55 | C20: Male | D20: Lagos | E20: 2026-06-11 | F20: Verified | G20: Activated | H20: 0 | I20: Current | J20: 9 | K20: 89307 | L20: 3
A21: CUST0020 | B21: 35 | C21: Female | D21: Lagos | E21: 2026-02-03 | F21: Verified | G21: Not Activated | I21: Savings | J21: 1 | K21: 9249 | L21: 4
A22: CUST0173 | B22: 51 | C22: Female | D22: Kano | E22: 2026-03-06 | F22: Verified | G22: Not Activated | I22: Savings | J22: 5 | K22: 32305 | L22: 1
A23: CUST0022 | B23: 39 | C23: Male | D23: Lagos | E23: 2026-02-18 | F23: Verified | G23: Activated | H23: 2 | I23: Savings | J23: 31 | K23: 84785 | L23: 4
A24: CUST0023 | B24: 53 | C24: Male | D24: Lagos | E24: 2026-05-19 | F24: Verified | G24: Not Activated | I24: Premium | J24: 1 | K24: 4224 | L24: 4
A25: CUST0024 | B25: 49 | C25: Female | D25: Lagos | E25: 2026-04-13 | F25: Pending | G25: Not Activated | I25: Savings | J25: 3 | K25: 17535 | L25: 4
A26: CUST0025 | C26: Female | D26: Rivers | E26: 2026-05-23 | F26: Verified | G26: Activated | H26: 3 | I26: Savings | J26: 7 | K26: 76923 | L26: 5
A27: CUST0171 | B27: 26 | C27: Female | D27: Oyo | E27: 2026-04-26 | F27: Verified | G27: Activated | H27: 2 | I27: Current | J27: 70 | K27: 838740 | L27: 5
A28: CUST0027 | B28: 29 | C28: Male | D28: Oyo | E28: 2026-06-22 | F28: Pending | G28: Not Activated | I28: Premium | J28: 4 | K28: 22132 | L28: 1
A29: CUST0170 | B29: 57 | C29: Male | D29: Lagos | E29: 2026-04-12 | F29: Pending | G29: Not Activated | I29: Savings | J29: 3 | K29: 32757 | L29: 1
A30: CUST0029 | B30: 43 | C30: Male | D30: Rivers | E30: 2026-03-18 | F30: Verified | G30: Not Activated | I30: Premium | J30: 0 | K30: 0 | L30: 1
A31: CUST0030 | B31: 22 | C31: Male | D31: Abuja | E31: 2026-02-03 | F31: Pending | G31: Not Activated | I31: Current | J31: 2 | K31: 12338 | L31: 2
A32: CUST0168 | B32: 53 | C32: Female | D32: Enugu | E32: 2026-02-10 | F32: Verified | G32: Not Activated | I32: Current | J32: 2 | K32: 19670 | L32: 2
A33: CUST0167 | B33: 26 | C33: Male | D33: Abuja | E33: 2026-04-24 | F33: Pending | G33: Not Activated | I33: Premium | J33: 2 | K33: 14384 | L33: 1
A34: CUST0165 | B34: 51 | C34: Female | D34: Lagos | E34: 2026-06-16 | F34: Verified | G34: Not Activated | I34: Savings | J34: 1 | K34: 9676 | L34: 4
A35: CUST0034 | B35: 53 | C35: Female | D35: Oyo | E35: 2026-01-29 | F35: Verified | G35: Not Activated | I35: Premium | J35: 4 | K35: 8360 | L35: 3
A36: CUST0035 | B36: 55 | C36: Male | D36: Abuja | E36: 2026-01-11 | F36: Verified | G36: Not Activated | I36: Current | J36: 0 | K36: 0 | L36: 2
A37: CUST0036 | B37: 33 | C37: Male | D37: Lagos | E37: 2026-05-24 | F37: Pending | G37: Not Activated | I37: Current | J37: 1 | K37: 5378 | L37: 2
A38: CUST0162 | B38: 20 | C38: Female | D38: Oyo | E38: 2026-04-22 | F38: Verified | G38: Not Activated | I38: Premium | J38: 0 | K38: 0 | L38: 4
A39: CUST0157 | B39: 58 | C39: Male | D39: Kano | E39: 2026-01-17 | F39: Verified | G39: Not Activated | I39: Savings | J39: 1 | K39: 2217 | L39: 2
... A46: CUST0150 | B46: 59 | C46: Female | D46: Kano | E46: 2026-02-05 | F46: Verified | G46: Not Activated | I46: Savings | J46: 1 | K46: 9185 | L46: 4
...

Sheet NovaPay_Onboarding(Main Table)
A1: Customer_ID | B1: Age | C1: Gender | D1: State | E1: Date_Registered | F1: Verification_Status | G1: Activation_Status | H1: Days_to_Activate | I1: Account_Type | J1: Monthly_Transactions | K1: Monthly_Transaction_Value | L1: Customer_Satisfaction_Score | M1: Age Groups | N1: Activation Speed
A2: CUST0001 | B2: 58 | C2: Male | D2: Lagos | E2: 46093 | F2: Verified | G2: Activated | H2: 1 | I2: Current | J2: 69 | K2: 201756 | L2: 5 | M2: {=_xlfn.IFS(Table1[[#This Row],[Age]]="", "Missing", Table1[[#This Row],[Age]]<20, "Below 20", Table1[[#This Row],[Age]]<30, "20-29", Table1[[#This Row],[Age]]<40, "30-39", Table1[[#This Row],[Age]]<50, "40-49", Table1[[#This Row],[Age]]<60, "50-59", Table1[[#This Row],[Age]]>=60, "60+")} -> 50-59 | N2: {=_xlfn.IFS(Table1[[#This Row],[Days_to_Activate]]<=3, "Fast", Table1[[#This Row],[Days_to_Activate]]<=7, "Moderate", Table1[[#This Row],[Days_to_Activate]]<=14, "Slow", Table1[[#This Row],[Days_to_Activate]]>14, "Outlier")} -> Fast
A3: CUST0002 | B3: 45 | C3: Male | D3: Lagos | E3: 46078 | F3: Verified | G3: Activated | H3: 8 | I3: Savings | J3: 69 | K3: 577737 | L3: 2 | M3: {=_xlfn.IFS(Table1[[#This Row],[Age]]="", "Missing", Table1[[#This Row],[Age]]<20, "Below 20", Table1[[#This Row],[Age]]<30, "20-29", Table1[[#This Row],[Age]]<40, "30-39", Table1[[#This Row],[Age]]<50, "40-49", Table1[[#This Row],[Age]]<60, "50-59", Table1[[#This Row],[Age]]>=60, "60+")} -> 40-49 | N3: {=_xlfn.IFS(Table1[[#This Row],[Days_to_Activate]]<=3, "Fast", Table1[[#This Row],[Days_to_Activate]]<=7, "Moderate", Table1[[#This Row],[Days_to_Activate]]<=14, "Slow", Table1[[#This Row],[Days_to_Activate]]>14, "Outlier")} -> Slow
A4: CUST0003 | B4: 46 | C4: Female | D4: Kano | E4: 46024 | F4: Verified | G4: Activated | H4: 6 | I4: Savings | J4: 19 | K4: 95513 | L4: 3 | M4: {=_xlfn.IFS(Table1[[#This Row],[Age]]="", "Missing", Table1[[#This Row],[Age]]<20, "Below 20", Table1[[#This Row],[Age]]<30, "20-29", Table1[[#This Row],[Age]]<40, "30-39", Table1[[#This Row],[Age]]<50, "40-49", Table1[[#This Row],[Age]]<60, "50-59", Table1[[#This Row],[Age]]>=60, "60+")} -> 40-49 | N4: {=_xlfn.IFS(Table1[[#This Row],[Days_to_Activate]]<=3, "Fast", Table1[[#This Row],[Days_to_Activate]]<=7, "Moderate", Table1[[#This Row],[Days_to_Activate]]<=14, "Slow", Table1[[#This Row],[Days_to_Activate]]>14, "Outlier")} -> Moderate
A5: CUST0004 | B5: 24 | C5: Male | D5: Lagos | E5: 46114 | F5: Verified | G5: Activated | H5: 12 | I5: Savings | J5: 58 | K5: 596530 | L5: 1 | M5: {=_xlfn.IFS(Table1[[#This Row],[Age]]="", "Missing", Table1[[#This Row],[Age]]<20, "Below 20", Table1[[#This Row],[Age]]<30, "20-29", Table1[[#This Row],[Age]]<40, "30-39", Table1[[#This Row],[Age]]<50, "40-49", Table1[[#This Row],[Age]]<60, "50-59", Table1[[#This Row],[Age]]>=60, "60+")} -> 20-29 | N5: {=_xlfn.IFS(Table1[[#This Row],[Days_to_Activate]]<=3, "Fast", Table1[[#This Row],[Days_to_Activate]]<=7, "Moderate", Table1[[#This Row],[Days_to_Activate]]<=14, "Slow", Table1[[#This Row],[Days_to_Activate]]>14, "Outlier")} -> Slow
A6: CUST0005 | B6: 42 | C6: Male | D6: Oyo | E6: 46183 | F6: Verified | G6: Activated | H6: 9 | I6: Savings | J6: 8 | K6: 18000 | L6: 2 | M6: {=_xlfn.IFS(Table1[[#This Row],[Age]]="", "Missing", Table1[[#This Row],[Age]]<20, "Below 20", Table1[[#This Row],[Age]]<30, "20-29", Table1[[#This Row],[Age]]<40, "30-39", Table1[[#This Row],[Age]]<50, "40-49", Table1[[#This Row],[Age]]<60, "50-59", Table1[[#This Row],[Age]]>=60, "60+")} -> 40-49 | N6: {=_xlfn.IFS(Table1[[#This Row],[Days_to_Activate]]<=3, "Fast", Table1[[#This Row],[Days_to_Activate]]<=7, "Moderate", Table1[[#This Row],[Days_to_Activate]]<=14, "Slow", Table1[[#This Row],[Days_to_Activate]]>14, "Outlier")} -> Slow
A7: CUST0006 | B7: 36 | C7: Male | D7: Enugu | E7: 46048 | F7: Verified | G7: Activated | H7: 13 | I7: Savings | J7: 47 | K7: 344040 | L7: 2 | M7: {=_xlfn.IFS(Table1[[#This Row],[Age]]="", "Missing", Table1[[#This Row],[Age]]<20, "Below 20", Table1[[#This Row],[Age]]<30, "20-29", Table1[[#This Row],[Age]]<40, "30-39", Table1[[#This Row],[Age]]<50, "40-49", Table1[[#This Row],[Age]]<60, "50-59", Table1[[#This Row],[Age]]>=60, "60+")} -> 30-39 | N7: {=_xlfn.IFS(Table1[[#This Row],[Days_to_Activate]]<=3, "Fast", Table1[[#This Row],[Days_to_Activate]]<=7, "Moderate", Table1[[#This Row],[Days_to_Activate]]<=14, "Slow", Table1[[#This Row],[Days_to_Activate]]>14, "Outlier")} -> Slow
A8: CUST0007 | B8: 60 | C8: Female | D8: Rivers | E8: 46197 | F8: Verified | G8: Activated | H8: 2 | I8: Savings | J8: 31 | K8: 129487 | L8: 4 | M8: {=_xlfn.IFS(Table1[[#This Row],[Age]]="", "Missing", Table1[[#This Row],[Age]]<20, "Below 20", Table1[[#This Row],[Age]]<30, "20-29", Table1[[#This Row],[Age]]<40, "30-39", Table1[[#This Row],[Age]]<50, "40-49", Table1[[#This Row],[Age]]<60, "50-59", Table1[[#This Row],[Age]]>=60, "60+")} -> 60+ | N8: {=_xlfn.IFS(Table1[[#This Row],[Days_to_Activate]]<=3, "Fast", Table1[[#This Row],[Days_to_Activate]]<=7, "Moderate", Table1[[#This Row],[Days_to_Activate]]<=14, "Slow", Table1[[#This Row],[Days_to_Activate]]>14, "Outlier")} -> Fast
A9: CUST0008 | B9: 42 | C9: Female | D9: Kaduna | E9: 46186 | F9: Verified | G9: Activated | H9: 5 | I9: Current | J9: 7 | K9: 36764 | L9: 1 | M9: {=_xlfn.IFS(Table1[[#This Row],[Age]]="", "Missing", Table1[[#This Row],[Age]]<20, "Below 20", Table1[[#This Row],[Age]]<30, "20-29", Table1[[#This Row],[Age]]<40, "30-39", Table1[[#This Row],[Age]]<50, "40-49", Table1[[#This Row],[Age]]<60, "50-59", Table1[[#This Row],[Age]]>=60, "60+")} -> 40-49 | N9: {=_xlfn.IFS(Table1[[#This Row],[Days_to_Activate]]<=3, "Fast", Table1[[#This Row],[Days_to_Activate]]<=7, "Moderate", Table1[[#This Row],[Days_to_Activate]]<=14, "Slow", Table1[[#This Row],[Days_to_Activate]]>14, "Outlier")} -> Moderate
A10: CUST0009 | B10: 38 | C10: Female | D10: Lagos | E10: 46077 | F10: Pending | G10: Not Activated | I10: Current | J10: 1 | K10: 9679 | L10: 4 | M10: {=_xlfn.IFS(Table1[[#This Row],[Age]]="", "Missing", Table1[[#This Row],[Age]]<20, "Below 20", Table1[[#This Row],[Age]]<30, "20-29", Table1[[#This Row],[Age]]<40, "30-39", Table1[[#This Row],[Age]]<50, "40-49", Table1[[#This Row],[Age]]<60, "50-59", Table1[[#This Row],[Age]]>=60, "60+")} -> 30-39 | N10: {=_xlfn.IFS(Table1[[#This Row],[Days_to_Activate]]<=3, "Fast", Table1[[#This Row],[Days_to_Activate]]<=7, "Moderate", Table1[[#This Row],[Days_to_Activate]]<=14, "Slow", Table1[[#This Row],[Days_to_Activate]]>14, "Outlier")} -> Fast
A11: CUST0010 | B11: 59 | C11: Female | D11: Lagos | E11: 46058 | F11: Verified | G11: Activated | H11: 5 | I11: Current | J11: 54 | K11: 597240 | L11: 4 | M11: {=_xlfn.IFS(Table1[[#This Row],[Age]]="", "Missing", Table1[[#This Row],[Age]]<20, "Below 20", Table1[[#This Row],[Age]]<30, "20-29", Table1[[#This Row],[Age]]<40, "30-39", Table1[[#This Row],[Age]]<50, "40-49", Table1[[#This Row],[Age]]<60, "50-59", Table1[[#This Row],[Age]]>=60, "60+")} -> 50-59 | N11: {=_xlfn.IFS(Table1[[#This Row],[Days_to_Activate]]<=3, "Fast", Table1[[#This Row],[Days_to_Activate]]<=7, "Moderate", Table1[[#This Row],[Days_to_Activate]]<=14, "Slow", Table1[[#This Row],[Days_to_Activate]]>14, "Outlier")} -> Moderate
A12: CUST0011 | B12: 41 | C12: Male | D12: Kaduna | E12: 46058 | F12: Verified | G12: Activated | H12: 0 | I12: Current | J12: 19 | K12: 223820 | L12: 3 | M12: {=_xlfn.IFS(Table1[[#This Row],[Age]]="", "Missing", Table1[[#This Row],[Age]]<20, "Below 20", Table1[[#This Row],[Age]]<30, "20-29", Table1[[#This Row],[Age]]<40, "30-39", Table1[[#This Row],[Age]]<50, "40-49", Table1[[#This Row],[Age]]<60, "50-59", Table1[[#This Row],[Age]]>=60, "60+")} -> 40-49 | N12: {=_xlfn.IFS(Table1[[#This Row],[Days_to_Activate]]<=3, "Fast", Table1[[#This Row],[Days_to_Activate]]<=7, "Moderate", Table1[[#This Row],[Days_to_Activate]]<=14, "Slow", Table1[[#This Row],[Days_to_Activate]]>14, "Outlier")} -> Fast
A13: CUST0012 | B13: 45 | C13: Male | D13: Lagos | E13: 46175 | F13: Pending | G13: Not Activated | I13: Premium | J13: 0 | K13: 0 | L13: 3 | M13: {=_xlfn.IFS(Table1[[#This Row],[Age]]="", "Missing", Table1[[#This Row],[Age]]<20, "Below 20", Table1[[#This Row],[Age]]<30, "20-29", Table1[[#This Row],[Age]]<40, "30-39", Table1[[#This Row],[Age]]<50, "40-49", Table1[[#This Row],[Age]]<60, "50-59", Table1[[#This Row],[Age]]>=60, "60+")} -> 40-49 | N13: {=_xlfn.IFS(Table1[[#This Row],[Days_to_Activate]]<=3, "Fast", Table1[[#This Row],[Days_to_Activate]]<=7, "Moderate", Table1[[#This Row],[Days_to_Activate]]<=14, "Slow", Table1[[#This Row],[Days_to_Activate]]>14, "Outlier")} -> Fast
A14: CUST0013 | B14: 59 | C14: Female | D14: Lagos | E14: 46134 | F14: Verified | G14: Activated | H14: 11 | I14: Current | J14: 33 | K14: 320133 | L14: 2 | M14: {=_xlfn.IFS(Table1[[#This Row],[Age]]="", "Missing", Table1[[#This Row],[Age]]<20, "Below 20", Table1[[#This Row],[Age]]<30, "20-29", Table1[[#This Row],[Age]]<40, "30-39", Table1[[#This Row],[Age]]<50, "40-49", Table1[[#This Row],[Age]]<60, "50-59", Table1[[#This Row],[Age]]>=60, "60+")} -> 50-59 | N14: {=_xlfn.IFS(Table1[[#This Row],[Days_to_Activate]]<=3, "Fast", Table1[[#This Row],[Days_to_Activate]]<=7, "Moderate", Table1[[#This Row],[Days_to_Activate]]<=14, "Slow", Table1[[#This Row],[Days_to_Activate]]>14, "Outlier")} -> Slow
A15: CUST0014 | B15: 50 | C15: Male | D15: Enugu | E15: 46099 | F15: Verified | G15: Activated | H15: 3 | I15: Savings | J15: 20 | K15: 206740 | L15: 5 | M15: {=_xlfn.IFS(Table1[[#This Row],[Age]]="", "Missing", Table1[[#This Row],[Age]]<20, "Below 20", Table1[[#This Row],[Age]]<30, "20-29", Table1[[#This Row],[Age]]<40, "30-39", Table1[[#This Row],[Age]]<50, "40-49", Table1[[#This Row],[Age]]<60, "50-59", Table1[[#This Row],[Age]]>=60, "60+")} -> 50-59 | N15: {=_xlfn.IFS(Table1[[#This Row],[Days_to_Activate]]<=3, "Fast", Table1[[#This Row],[Days_to_Activate]]<=7, "Moderate", Table1[[#This Row],[Days_to_Activate]]<=14, "Slow", Table1[[#This Row],[Days_to_Activate]]>14, "Outlier")} -> Fast
A16: CUST0015 | B16: 18 | C16: Female | D16: Abuja | E16: 46051 | F16: Pending | G16: Not Activated | I16: Current | J16: 2 | K16: 10846 | L16: 1 | M16: {=_xlfn.IFS(Table1[[#This Row],[Age]]="", "Missing", Table1[[#This Row],[Age]]<20, "Below 20", Table1[[#This Row],[Age]]<30, "20-29", Table1[[#This Row],[Age]]<40, "30-39", Table1[[#This Row],[Age]]<50, "40-49", Table1[[#This Row],[Age]]<60, "50-59", Table1[[#This Row],[Age]]>=60, "60+")} -> Below 20 | N16: {=_xlfn.IFS(Table1[[#This Row],[Days_to_Activate]]<=3, "Fast", Table1[[#This Row],[Days_to_Activate]]<=7, "Moderate", Table1[[#This Row],[Days_to_Activate]]<=14, "Slow", Table1[[#This Row],[Days_to_Activate]]>14, "Outlier")} -> Fast
A17: CUST0016 | B17: 33 | C17: Male | D17: Lagos | E17: 46147 | F17: Verified | G17: Not Activated | I17: Savings | J17: 1 | K17: 3603 | L17: 4 | M17: {=_xlfn.IFS(Table1[[#This Row],[Age]]="", "Missing", Table1[[#This Row],[Age]]<20, "Below 20", Table1[[#This Row],[Age]]<30, "20-29", Table1[[#This Row],[Age]]<40, "30-39", Table1[[#This Row],[Age]]<50, "40-49", Table1[[#This Row],[Age]]<60, "50-59", Table1[[#This Row],[Age]]>=60, "60+")} -> 30-39 | N17: {=_xlfn.IFS(Table1[[#This Row],[Days_to_Activate]]<=3, "Fast", Table1[[#This Row],[Days_to_Activate]]<=7, "Moderate", Table1[[#This Row],[Days_to_Activate]]<=14, "Slow", Table1[[#This Row],[Days_to_Activate]]>14, "Outlier")} -> Fast
A18: CUST0017 | B18: 53 | C18: Male | D18: Lagos | E18: 46178 | F18: Verified | G18: Activated | H18: 8 | I18: Current | J18: 25 | K18: 165175 | L18: 4 | M18: {=_xlfn.IFS(Table1[[#This Row],[Age]]="", "Missing", Table1[[#This Row],[Age]]<20, "Below 20", Table1[[#This Row],[Age]]<30, "20-29", Table1[[#This Row],[Age]]<40, "30-39", Table1[[#This Row],[Age]]<50, "40-49", Table1[[#This Row],[Age]]<60, "50-59", Table1[[#This Row],[Age]]>=60, "60+")} -> 50-59 | N18: {=_xlfn.IFS(Table1[[#This Row],[Days_to_Activate]]<=3, "Fast", Table1[[#This Row],[Days_to_Activate]]<=7, "Moderate", Table1[[#This Row],[Days_to_Activate]]<=14, "Slow", Table1[[#This Row],[Days_to_Activate]]>14, "Outlier")} -> Slow
A19: CUST0018 | B19: 60 | C19: Female | D19: Abuja | E19: 46155 | F19: Verified | G19: Activated | H19: 1 | I19: Savings | J19: 75 | K19: 793125 | L19: 3 | M19: {=_xlfn.IFS(Table1[[#This Row],[Age]]="", "Missing", Table1[[#This Row],[Age]]<20, "Below 20", Table1[[#This Row],[Age]]<30, "20-29", Table1[[#This Row],[Age]]<40, "30-39", Table1[[#This Row],[Age]]<50, "40-49", Table1[[#This Row],[Age]]<60, "50-59", Table1[[#This Row],[Age]]>=60, "60+")} -> 60+ | N19: {=_xlfn.IFS(Table1[[#This Row],[Days_to_Activate]]<=3, "Fast", Table1[[#This Row],[Days_to_Activate]]<=7, "Moderate", Table1[[#This Row],[Days_to_Activate]]<=14, "Slow", Table1[[#This Row],[Days_to_Activate]]>14, "Outlier")} -> Fast
A20: CUST0019 | B20: 55 | C20: Male | D20: Lagos | E20: 46184 | F20: Verified | G20: Activated | H20: 0 | I20: Current | J20: 9 | K20: 89307 | L20: 3 | M20: {=_xlfn.IFS(Table1[[#This Row],[Age]]="", "Missing", Table1[[#This Row],[Age]]<20, "Below 20", Table1[[#This Row],[Age]]<30, "20-29", Table1[[#This Row],[Age]]<40, "30-39", Table1[[#This Row],[Age]]<50, "40-49", Table1[[#This Row],[Age]]<60, "50-59", Table1[[#This Row],[Age]]>=60, "60+")} -> 50-59 | N20: {=_xlfn.IFS(Table1[[#This Row],[Days_to_Activate]]<=3, "Fast", Table1[[#This Row],[Days_to_Activate]]<=7, "Moderate", Table1[[#This Row],[Days_to_Activate]]<=14, "Slow", Table1[[#This Row],[Days_to_Activate]]>14, "Outlier")} -> Fast
A21: CUST0020 | B21: 35 | C21: Female | D21: Lagos | E21: 46056 | F21: Verified | G21: Not Activated | I21: Savings | J21: 1 | K21: 9249 | L21: 4 | M21: {=_xlfn.IFS(Table1[[#This Row],[Age]]="", "Missing", Table1[[#This Row],[Age]]<20, "Below 20", Table1[[#This Row],[Age]]<30, "20-29", Table1[[#This Row],[Age]]<40, "30-39", Table1[[#This Row],[Age]]<50, "40-49", Table1[[#This Row],[Age]]<60, "50-59", Table1[[#This Row],[Age]]>=60, "60+")} -> 30-39 | N21: {=_xlfn.IFS(Table1[[#This Row],[Days_to_Activate]]<=3, "Fast", Table1[[#This Row],[Days_to_Activate]]<=7, "Moderate", Table1[[#This Row],[Days_to_Activate]]<=14, "Slow", Table1[[#This Row],[Days_to_Activate]]>14, "Outlier")} -> Fast
A22: CUST0021 | B22: 30 | C22: Male | D22: Lagos | E22: 46133 | F22: Verified | G22: Activated | H22: 13 | I22: Current | J22: 12 | K22: 29916 | L22: 4 | M22: {=_xlfn.IFS(Table1[[#This Row],[Age]]="", "Missing", Table1[[#This Row],[Age]]<20, "Below 20", Table1[[#This Row],[Age]]<30, "20-29", Table1[[#This Row],[Age]]<40, "30-39", Table1[[#This Row],[Age]]<50, "40-49", Table1[[#This Row],[Age]]<60, "50-59", Table1[[#This Row],[Age]]>=60, "60+")} -> 30-39 | N22: {=_xlfn.IFS(Table1[[#This Row],[Days_to_Activate]]<=3, "Fast", Table1[[#This Row],[Days_to_Activate]]<=7, "Moderate", Table1[[#This Row],[Days_to_Activate]]<=14, "Slow", Table1[[#This Row],[Days_to_Activate]]>14, "Outlier")} -> Slow
A23: CUST0022 | B23: 39 | C23: Male | D23: Lagos | E23: 46071 | F23: Verified | G23: Activated | H23: 2 | I23: Savings | J23: 31 | K23: 84785 | L23: 4 | M23: {=_xlfn.IFS(Table1[[#This Row],[Age]]="", "Missing", Table1[[#This Row],[Age]]<20, "Below 20", Table1[[#This Row],[Age]]<30, "20-29", Table1[[#This Row],[Age]]<40, "30-39", Table1[[#This Row],[Age]]<50, "40-49", Table1[[#This Row],[Age]]<60, "50-59", Table1[[#This Row],[Age]]>=60, "60+")} -> 30-39 | N23: {=_xlfn.IFS(Table1[[#This Row],[Days_to_Activate]]<=3, "Fast", Table1[[#This Row],[Days_to_Activate]]<=7, "Moderate", Table1[[#This Row],[Days_to_Activate]]<=14, "Slow", Table1[[#This Row],[Days_to_Activate]]>14, "Outlier")} -> Fast
A24: CUST0023 | B24: 53 | C24: Male | D24: Lagos | E24: 46161 | F24: Verified | G24: Not Activated | I24: Premium | J24: 1 | K24: 4224 | L24: 4 | M24: {=_xlfn.IFS(Table1[[#This Row],[Age]]="", "Missing", Table1[[#This Row],[Age]]<20, "Below 20", Table1[[#This Row],[Age]]<30, "20-29", Table1[[#This Row],[Age]]<40, "30-39", Table1[[#This Row],[Age]]<50, "40-49", Table1[[#This Row],[Age]]<60, "50-59", Table1[[#This Row],[Age]]>=60, "60+")} -> 50-59 | N24: {=_xlfn.IFS(Table1[[#This Row],[Days_to_Activate]]<=3, "Fast", Table1[[#This Row],[Days_to_Activate]]<=7, "Moderate", Table1[[#This Row],[Days_to_Activate]]<=14, "Slow", Table1[[#This Row],[Days_to_Activate]]>14, "Outlier")} -> Fast
A25: CUST0024 | B25: 49 | C25: Female | D25: Lagos | E25: 46125 | F25: Pending | G25: Not Activated | I25: Savings | J25: 3 | K25: 17535 | L25: 4 | M25: {=_xlfn.IFS(Table1[[#This Row],[Age]]="", "Missing", Table1[[#This Row],[Age]]<20, "Below 20", Table1[[#This Row],[Age]]<30, "20-29", Table1[[#This Row],[Age]]<40, "30-39", Table1[[#This Row],[Age]]<50, "40-49", Table1[[#This Row],[Age]]<60, "50-59", Table1[[#This Row],[Age]]>=60, "60+")} -> 40-49 | N25: {=_xlfn.IFS(Table1[[#This Row],[Days_to_Activate]]<=3, "Fast", Table1[[#This Row],[Days_to_Activate]]<=7, "Moderate", Table1[[#This Row],[Days_to_Activate]]<=14, "Slow", Table1[[#This Row],[Days_to_Activate]]>14, "Outlier")} -> Fast
A26: CUST0025 | C26: Female | D26: Rivers | E26: 46165 | F26: Verified | G26: Activated | H26: 3 | I26: Savings | J26: 7 | K26: 76923 | L26: 5 | M26: {=_xlfn.IFS(Table1[[#This Row],[Age]]="", "Missing", Table1[[#This Row],[Age]]<20, "Below 20", Table1[[#This Row],[Age]]<30, "20-29", Table1[[#This Row],[Age]]<40, "30-39", Table1[[#This Row],[Age]]<50, "40-49", Table1[[#This Row],[Age]]<60, "50-59", Table1[[#This Row],[Age]]>=60, "60+")} -> Missing | N26: {=_xlfn.IFS(Table1[[#This Row],[Days_to_Activate]]<=3, "Fast", Table1[[#This Row],[Days_to_Activate]]<=7, "Moderate", Table1[[#This Row],[Days_to_Activate]]<=14, "Slow", Table1[[#This Row],[Days_to_Activate]]>14, "Outlier")} -> Fast
A27: CUST0026 | B27: 52 | C27: Male | D27: Rivers | E27: 46037 | F27: Verified | G27: Activated | H27: 14 | I27: Current | J27: 20 | K27: 48620 | L27: 1 | M27: {=_xlfn.IFS(Table1[[#This Row],[Age]]="", "Missing", Table1[[#This Row],[Age]]<20, "Below 20", Table1[[#This Row],[Age]]<30, "20-29", Table1[[#This Row],[Age]]<40, "30-39", Table1[[#This Row],[Age]]<50, "40-49", Table1[[#This Row],[Age]]<60, "50-59", Table1[[#This Row],[Age]]>=60, "60+")} -> 50-59 | N27: {=_xlfn.IFS(Table1[[#This Row],[Days_to_Activate]]<=3, "Fast", Table1[[#This Row],[Days_to_Activate]]<=7, "Moderate", Table1[[#This Row],[Days_to_Activate]]<=14, "Slow", Table1[[#This Row],[Days_to_Activate]]>14, "Outlier")} -> Slow
A28: CUST0027 | B28: 29 | C28: Male | D28: Oyo | E28: 46195 | F28: Pending | G28: Not Activated | I28: Premium | J28: 4 | K28: 22132 | L28: 1 | M28: {=_xlfn.IFS(Table1[[#This Row],[Age]]="", "Missing", Table1[[#This Row],[Age]]<20, "Below 20", Table1[[#This Row],[Age]]<30, "20-29", Table1[[#This Row],[Age]]<40, "30-39", Table1[[#This Row],[Age]]<50, "40-49", Table1[[#This Row],[Age]]<60, "50-59", Table1[[#This Row],[Age]]>=60, "60+")} -> 20-29 | N28: {=_xlfn.IFS(Table1[[#This Row],[Days_to_Activate]]<=3, "Fast", Table1[[#This Row],[Days_to_Activate]]<=7, "Moderate", Table1[[#This Row],[Days_to_Activate]]<=14, "Slow", Table1[[#This Row],[Days_to_Activate]]>14, "Outlier")} -> Fast
A29: CUST0028 | B29: 57 | C29: Male | D29: Abuja | E29: 46172 | F29: Verified | G29: Activated | H29: 4 | I29: Savings | J29: 40 | K29: 216400 | L29: 3 | M29: {=_xlfn.IFS(Table1[[#This Row],[Age]]="", "Missing", Table1[[#This Row],[Age]]<20, "Below 20", Table1[[#This Row],[Age]]<30, "20-29", Table1[[#This Row],[Age]]<40, "30-39", Table1[[#This Row],[Age]]<50, "40-49", Table1[[#This Row],[Age]]<60, "50-59", Table1[[#This Row],[Age]]>=60, "60+")} -> 50-59 | N29: {=_xlfn.IFS(Table1[[#This Row],[Days_to_Activate]]<=3, "Fast", Table1[[#This Row],[Days_to_Activate]]<=7, "Moderate", Table1[[#This Row],[Days_to_Activate]]<=14, "Slow", Table1[[#This Row],[Days_to_Activate]]>14, "Outlier")} -> Moderate
A30: CUST0029 | B30: 43 | C30: Male | D30: Rivers | E30: 46099 | F30: Verified | G30: Not Activated | I30: Premium | J30: 0 | K30: 0 | L30: 1 | M30: {=_xlfn.IFS(Table1[[#This Row],[Age]]="", "Missing", Table1[[#This Row],[Age]]<20, "Below 20", Table1[[#This Row],[Age]]<30, "20-29", Table1[[#This Row],[Age]]<40, "30-39", Table1[[#This Row],[Age]]<50, "40-49", Table1[[#This Row],[Age]]<60, "50-59", Table1[[#This Row],[Age]]>=60, "60+")} -> 40-49 | N30: {=_xlfn.IFS(Table1[[#This Row],[Days_to_Activate]]<=3, "Fast", Table1[[#This Row],[Days_to_Activate]]<=7, "Moderate", Table1[[#This Row],[Days_to_Activate]]<=14, "Slow", Table1[[#This Row],[Days_to_Activate]]>14, "Outlier")} -> Fast
A31: CUST0030 | B31: 22 | C31: Male | D31: Abuja | E31: 46056 | F31: Pending | G31: Not Activated | I31: Current | J31: 2 | K31: 12338 | L31: 2 | M31: {=_xlfn.IFS(Table1[[#This Row],[Age]]="", "Missing", Table1[[#This Row],[Age]]<20, "Below 20", Table1[[#This Row],[Age]]<30, "20-29", Table1[[#This Row],[Age]]<40, "30-39", Table1[[#This Row],[Age]]<50, "40-49", Table1[[#This Row],[Age]]<60, "50-59", Table1[[#This Row],[Age]]>=60, "60+")} -> 20-29 | N31: {=_xlfn.IFS(Table1[[#This Row],[Days_to_Activate]]<=3, "Fast", Table1[[#This Row],[Days_to_Activate]]<=7, "Moderate", Table1[[#This Row],[Days_to_Activate]]<=14, "Slow", Table1[[#This Row],[Days_to_Activate]]>14, "Outlier")} -> Fast
A32: CUST0031 | B32: 46 | C32: Female | D32: Oyo | E32: 46190 | F32: Verified | G32: Activated | H32: 8 | I32: Savings | J32: 13 | K32: 48100 | L32: 3 | M32: {=_xlfn.IFS(Table1[[#This Row],[Age]]="", "Missing", Table1[[#This Row],[Age]]<20, "Below 20", Table1[[#This Row],[Age]]<30, "20-29", Table1[[#This Row],[Age]]<40, "30-39", Table1[[#This Row],[Age]]<50, "40-49", Table1[[#This Row],[Age]]<60, "50-59", Table1[[#This Row],[Age]]>=60, "60+")} -> 40-49 | N32: {=_xlfn.IFS(Table1[[#This Row],[Days_to_Activate]]<=3, "Fast", Table1[[#This Row],[Days_to_Activate]]<=7, "Moderate", Table1[[#This Row],[Days_to_Activate]]<=14, "Slow", Table1[[#This Row],[Days_to_Activate]]>14, "Outlier")} -> Slow
A33: CUST0032 | B33: 25 | C33: Male | D33: Rivers | E33: 46062 | F33: Verified | G33: Activated | H33: 11 | I33: Savings | J33: 33 | K33: 322740 | L33: 4 | M33: {=_xlfn.IFS(Table1[[#This Row],[Age]]="", "Missing", Table1[[#This Row],[Age]]<20, "Below 20", Table1[[#This Row],[Age]]<30, "20-29", Table1[[#This Row],[Age]]<40, "30-39", Table1[[#This Row],[Age]]<50, "40-49", Table1[[#This Row],[Age]]<60, "50-59", Table1[[#This Row],[Age]]>=60, "60+")} -> 20-29 | N33: {=_xlfn.IFS(Table1[[#This Row],[Days_to_Activate]]<=3, "Fast", Table1[[#This Row],[Days_to_Activate]]<=7, "Moderate", Table1[[#This Row],[Days_to_Activate]]<=14, "Slow", Table1[[#This Row],[Days_to_Activate]]>14, "Outlier")} -> Slow
A34: CUST0033 | B34: 34 | C34: Male | D34: Lagos | E34: 46131 | F34: Verified | G34: Activated | H34: 5 | I34: Current | J34: 33 | K34: 136851 | L34: 4 | M34: {=_xlfn.IFS(Table1[[#This Row],[Age]]="", "Missing", Table1[[#This Row],[Age]]<20, "Below 20", Table1[[#This Row],[Age]]<30, "20-29", Table1[[#This Row],[Age]]<40, "30-39", Table1[[#This Row],[Age]]<50, "40-49", Table1[[#This Row],[Age]]<60, "50-59", Table1[[#This Row],[Age]]>=60, "60+")} -> 30-39 | N34: {=_xlfn.IFS(Table1[[#This Row],[Days_to_Activate]]<=3, "Fast", Table1[[#This Row],[Days_to_Activate]]<=7, "Moderate", Table1[[#This Row],[Days_to_Activate]]<=14, "Slow", Table1[[#This Row],[Days_to_Activate]]>14, "Outlier")} -> Moderate
A35: CUST0034 | B35: 53 | C35: Female | D35: Oyo | E35: 46051 | F35: Verified | G35: Not Activated | I35: Premium | J35: 4 | K35: 8360 | L35: 3 | M35: {=_xlfn.IFS(Table1[[#This Row],[Age]]="", "Missing", Table1[[#This Row],[Age]]<20, "Below 20", Table1[[#This Row],[Age]]<30, "20-29", Table1[[#This Row],[Age]]<40, "30-39", Table1[[#This Row],[Age]]<50, "40-49", Table1[[#This Row],[Age]]<60, "50-59", Table1[[#This Row],[Age]]>=60, "60+")} -> 50-59 | N35: {=_xlfn.IFS(Table1[[#This Row],[Days_to_Activate]]<=3, "Fast", Table1[[#This Row],[Days_to_Activate]]<=7, "Moderate", Table1[[#This Row],[Days_to_Activate]]<=14, "Slow", Table1[[#This Row],[Days_to_Activate]]>14, "Outlier")} -> Fast
A36: CUST0035 | B36: 55 | C36: Male | D36: Abuja | E36: 46033 | F36: Verified | G36: Not Activated | I36: Current | J36: 0 | K36: 0 | L36: 2 | M36: {=_xlfn.IFS(Table1[[#This Row],[Age]]="", "Missing", Table1[[#This Row],[Age]]<20, "Below 20", Table1[[#This Row],[Age]]<30, "20-29", Table1[[#This Row],[Age]]<40, "30-39", Table1[[#This Row],[Age]]<50, "40-49", Table1[[#This Row],[Age]]<60, "50-59", Table1[[#This Row],[Age]]>=60, "60+")} -> 50-59 | N36: {=_xlfn.IFS(Table1[[#This Row],[Days_to_Activate]]<=3, "Fast", Table1[[#This Row],[Days_to_Activate]]<=7, "Moderate", Table1[[#This Row],[Days_to_Activate]]<=14, "Slow", Table1[[#This Row],[Days_to_Activate]]>14, "Outlier")} -> Fast
A37: CUST0036 | B37: 33 | C37: Male | D37: Lagos | E37: 46166 | F37: Pending | G37: Not Activated | I37: Current | J37: 1 | K37: 5378 | L37: 2 | M37: {=_xlfn.IFS(Table1[[#This Row],[Age]]="", "Missing", Table1[[#This Row],[Age]]<20, "Below 20", Table1[[#This Row],[Age]]<30, "20-29", Table1[[#This Row],[Age]]<40, "30-39", Table1[[#This Row],[Age]]<50, "40-49", Table1[[#This Row],[Age]]<60, "50-59", Table1[[#This Row],[Age]]>=60, "60+")} -> 30-39 | N37: {=_xlfn.IFS(Table1[[#This Row],[Days_to_Activate]]<=3, "Fast", Table1[[#This Row],[Days_to_Activate]]<=7, "Moderate", Table1[[#This Row],[Days_to_Activate]]<=14, "Slow", Table1[[#This Row],[Days_to_Activate]]>14, "Outlier")} -> Fast
A38: CUST0037 | B38: 29 | C38: Female | D38: Lagos | E38: 46108 | F38: Verified | G38: Activated | H38: 10 | I38: Current | J38: 31 | K38: 182001 | L38: 2 | M38: {=_xlfn.IFS(Table1[[#This Row],[Age]]="", "Missing", Table1[[#This Row],[Age]]<20, "Below 20", Table1[[#This Row],[Age]]<30, "20-29", Table1[[#This Row],[Age]]<40, "30-39", Table1[[#This Row],[Age]]<50, "40-49", Table1[[#This Row],[Age]]<60, "50-59", Table1[[#This Row],[Age]]>=60, "60+")} -> 20-29 | N38: {=_xlfn.IFS(Table1[[#This Row],[Days_to_Activate]]<=3, "Fast", Table1[[#This Row],[Days_to_Activate]]<=7, "Moderate", Table1[[#This Row],[Days_to_Activate]]<=14, "Slow", Table1[[#This Row],[Days_to_Activate]]>14, "Outlier")} -> Slow
A39: CUST0038 | B39: 24 | C39: Female | D39: Enugu | E39: 46143 | F39: Verified | G39: Activated | H39: 7 | I39: Savings | J39: 29 | K39: 149408 | L39: 1 | M39: {=_xlfn.IFS(Table1[[#This Row],[Age]]="", "Missing", Table1[[#This Row],[Age]]<20, "Below 20", Table1[[#This Row],[Age]]<30, "20-29", Table1[[#This Row],[Age]]<40, "30-39", Table1[[#This Row],[Age]]<50, "40-49", Table1[[#This Row],[Age]]<60, "50-59", Table1[[#This Row],[Age]]>=60, "60+")} -> 20-29 | N39: {=_xlfn.IFS(Table1[[#This Row],[Days_to_Activate]]<=3, "Fast", Table1[[#This Row],[Days_to_Activate]]<=7, "Moderate", Table1[[#This Row],[Days_to_Activate]]<=14, "Slow", Table1[[#This Row],[Days_to_Activate]]>14, "Outlier")} -> Moderate
A40: CUST0039 | B40: 60 | C40: Male | D40: Lagos | E40: 46094 | F40: Pending | G40: Not Activated | I40: Savings | J40: 5 | K40: 49230 | L40: 4 | M40: {=_xlfn.IFS(Table1[[#This Row],[Age]]="", "Missing", Table1[[#This Row],[Age]]<20, "Below 20", Table1[[#This Row],[Age]]<30, "20-29", Table1[[#This Row],[Age]]<40, "30-39", Table1[[#This Row],[Age]]<50, "40-49", Table1[[#This Row],[Age]]<60, "50-59", Table1[[#This Row],[Age]]>=60, "60+")} -> 60+ | N40: {=_xlfn.IFS(Table1[[#This Row],[Days_to_Activate]]<=3, "Fast", Table1[[#This Row],[Days_to_Activate]]<=7, "Moderate", Table1[[#This Row],[Days_to_Activate]]<=14, "Slow", Table1[[#This Row],[Days_to_Activate]]>14, "Outlier")} -> Fast
...

Sheet Pivot Tables
A3: States | B3: No. of Customers | M3: Activation Satus | N3: Count of Customer_ID
A4: Lagos | B4: 83 | M4: Activated | N4: 151
A5: Abuja | B5: 27 | M5: Not Activated | N5: 48
A6: Rivers | B6: 22 | M6: Grand Total | N6: 199
A7: Kano | B7: 20
A8: Oyo | B8: 19 | N8: =GETPIVOTDATA("Customer_ID",$M$3,"Activation_Status","Activated")/GETPIVOTDATA("Customer_ID",$M$3)*100 -> 75.879397
A9: Enugu | B9: 12
A10: Ogun | B10: 9
A11: Kaduna | B11: 7
A12: Grand Total | B12: 199
M13: Average of Days_to_Activate
M14: 7.7880795
G15: Total Customers | H15: Average Customer_Satisfaction_Score
C16: Row Labels | D16: No. of Monthly Transactions | G16: 199 | H16: 2.8341709
C17: Savings | D17: 27998220
C18: Current | D18: 10423553 | M18: Row Labels | N18: Average of Customer_Satisfaction_Score
C19: Premium | D19: 4186589 | M19: Outlier | N19: 4
C20: Grand Total | D20: 42608362 | K20: Count of Customer_ID | M20: Fast | N20: 3.2025316
K21: 199 | M21: Moderate | N21: 2.8913043
M22: Slow | N22: 2.3835616
M23: Grand Total | N23: 2.8341709
H26: Activation Status | I26: No. of Customers
H27: Activated | I27: 151 | L27: Account Type | M27: Sum of Monthly Transaction Values
H28: Not Activated | I28: 48 | L28: Savings | M28: 27998220
H29: Grand Total | I29: 199 | L29: Current | M29: 10423553
L30: Premium | M30: 4186589
L31: Grand Total | M31: 42608362
C34: Column Labels
C35: Activated | F35: Not Activated | I35: Total No. of Customers | J35: Total Average of Days_to_Activate | K35: Total Average of Customer_Satisfaction_Score
B36: States | C36: No. of Customers | D36: Average of Days_to_Activate | E36: Average of Customer_Satisfaction_Score | F36: No. of Customers | G36: Average of Days_to_Activate | H36: Average of Customer_Satisfaction_Score
B37: Abuja | C37: 21 | D37: 7.2857143 | E37: 2.9047619 | F37: 6 | H37: 2 | I37: 27 | J37: 7.2857143 | K37: 2.7037037
B38: Enugu | C38: 8 | D38: 12.25 | E38: 2.75 | F38: 4 | H38: 2.75 | I38: 12 | J38: 12.25 | K38: 2.75
B39: Kaduna | C39: 7 | D39: 5.4285714 | E39: 3.1428571 | I39: 7 | J39: 5.4285714 | K39: 3.1428571
B40: Kano | C40: 13 | D40: 7 | E40: 2.8461538 | F40: 7 | H40: 3.2857143 | I40: 20 | J40: 7 | K40: 3
B41: Lagos | C41: 60 | D41: 8.1 | E41: 2.8333333 | F41: 23 | H41: 2.826087 | I41: 83 | J41: 8.1 | K41: 2.8313253
B42: Ogun | C42: 7 | D42: 6.1428571 | E42: 2.7142857 | F42: 2 | H42: 2 | I42: 9 | J42: 6.1428571 | K42: 2.5555556
B43: Oyo | C43: 16 | D43: 6.75 | E43: 2.9375 | F43: 3 | H43: 2.6666667 | I43: 19 | J43: 6.75 | K43: 2.8947368
B44: Rivers | C44: 19 | D44: 8.3684211 | E44: 3 | F44: 3 | H44: 2 | I44: 22 | J44: 8.3684211 | K44: 2.8636364
B45: Grand Total | C45: 151 | D45: 7.7880795 | E45: 2.8807947 | F45: 48 | H45: 2.6875 | I45: 199 | J45: 7.7880795 | K45: 2.8341709
B50: Age Groups | C50: No. of Registrations
...

Sheet Dashboard
I1: CUSTOMER ACTIVATION DASHBOARD
B4: Total Customers | F4: Activation Rate | K4: Average Satisfaction | O4: Average Days to Activate | T4: State with Most Customers | Y4: Top Age Group
B6: =GETPIVOTDATA("Customer_ID",'Pivot Tables'!$K$20) -> 199 | F6: ='Pivot Tables'!N8 -> 75.879397 | L6: =GETPIVOTDATA("Average Customer_Satisfaction_Score",'Pivot Tables'!$G$15) -> 2.8341709 | Q6: =GETPIVOTDATA("Days_to_Activate",'Pivot Tables'!$M$13) -> 7.7880795 | V6: =INDEX('Pivot Tables'!A4:A11,MATCH(MAX('Pivot Tables'!B4:B11),'Pivot Tables'!B4:B11,0)) -> Lagos | AA6: =INDEX('Pivot Tables'!B51:B57,MATCH(MAX('Pivot Tables'!C51:C57),'Pivot Tables'!C51:C57,0)) -> 40-49

Sheet Project Insights
A1: OVERVIEW
A3: This analysis looks at how well customers are being activated, how satisfied they are, where customers are registering from, and which account types are generating the most transaction value. The goal is to understand what is going well and where there may be opportunities to improve the customer experience.
A5: WHAT THE DATA TELLS US
A7: Most customers are successfully being activated, with 151 out of 199 customers activated (75.9%). However, activation is not always happening quickly. The average activation time is around 8 days, while one customer took 45 days, standing out as a possible issue worth investigating.
A9: Customer satisfaction appears relatively low. This raises an important question: could activation speed or other customer/account factors be contributing to lower satisfaction? Further analysis would be needed to understand the relationship.
A11: Customer registration is also uneven across states. Lagos has the most customers (83), while Kaduna has the fewest (7). This difference could point to factors affecting customer registration in different locations.
A13: The 40–49 age group has the highest number of registrations, while Savings accounts generate the highest monthly transaction value. These patterns help show which customer group and account type are particularly active in the dataset.
A15: WHAT SHOULD BE LOOKED AT NEXT?
A17: Investigate why some customers take much longer to activate.
A18: Look into whether activation problems are connected to lower customer satisfaction.
A19: Investigate why customer registration is much lower in Kaduna.
A20: Continue monitoring the customer groups and account types showing the highest activity.
